<sdf version='1.7'>
  <world name='default'>
    <light name='sun' type='directional'>
      <cast_shadows>1</cast_shadows>
      <pose>0 0 10 0 -0 0</pose>
      <diffuse>0.8 0.8 0.8 1</diffuse>
      <specular>0.2 0.2 0.2 1</specular>
      <attenuation>
        <range>1000</range>
        <constant>0.9</constant>
        <linear>0.01</linear>
        <quadratic>0.001</quadratic>
      </attenuation>
      <direction>-0.5 0.1 -0.9</direction>
      <spot>
        <inner_angle>0</inner_angle>
        <outer_angle>0</outer_angle>
        <falloff>0</falloff>
      </spot>
    </light>
    <model name='ground_plane'>
      <static>1</static>
      <link name='link'>
        <collision name='collision'>
          <geometry>
            <plane>
              <normal>0 0 1</normal>
              <size>100 100</size>
            </plane>
          </geometry>
          <surface>
            <contact>
              <collide_bitmask>65535</collide_bitmask>
              <ode/>
            </contact>
            <friction>
              <ode>
                <mu>100</mu>
                <mu2>50</mu2>
              </ode>
              <torsional>
                <ode/>
              </torsional>
            </friction>
            <bounce/>
          </surface>
          <max_contacts>10</max_contacts>
        </collision>
        <visual name='visual'>
          <cast_shadows>0</cast_shadows>
          <geometry>
            <plane>
              <normal>0 0 1</normal>
              <size>100 100</size>
            </plane>
          </geometry>
          <material>
            <script>
              <uri>file://media/materials/scripts/gazebo.material</uri>
              <name>Gazebo/Grey</name>
            </script>
          </material>
        </visual>
        <self_collide>0</self_collide>
        <enable_wind>0</enable_wind>
        <kinematic>0</kinematic>
      </link>
    </model>
    <gravity>0 0 -9.8</gravity>
    <magnetic_field>6e-06 2.3e-05 -4.2e-05</magnetic_field>
    <atmosphere type='adiabatic'/>
    <physics type='ode'>
      <max_step_size>0.001</max_step_size>
      <real_time_factor>1</real_time_factor>
      <real_time_update_rate>1000</real_time_update_rate>
    </physics>
    <scene>
      <ambient>0.4 0.4 0.4 1</ambient>
      <background>0.7 0.7 0.7 1</background>
      <shadows>1</shadows>
    </scene>
    <audio>
      <device>default</device>
    </audio>
    <wind/>
    <spherical_coordinates>
      <surface_model>EARTH_WGS84</surface_model>
      <latitude_deg>0</latitude_deg>
      <longitude_deg>0</longitude_deg>
      <elevation>0</elevation>
      <heading_deg>0</heading_deg>
    </spherical_coordinates>
    <model name='robot_dd'>
      <link name='base_link'>
        <inertial>
          <pose>0.065 0 0.0625 0 -0 0</pose>
          <mass>0.6</mass>
          <inertia>
            <ixx>0.00525625</ixx>
            <ixy>0</ixy>
            <ixz>0.0005625</ixz>
            <iyy>0.00593125</iyy>
            <iyz>0</iyz>
            <izz>0.008275</izz>
          </inertia>
        </inertial>
        <collision name='base_link_fixed_joint_lump__chassis_collision'>
          <pose>0.05 0 0.075 0 -0 0</pose>
          <geometry>
            <box>
              <size>0.3 0.3 0.15</size>
            </box>
          </geometry>
          <surface>
            <contact>
              <ode/>
            </contact>
            <friction>
              <ode/>
              <torsional>
                <ode/>
              </torsional>
            </friction>
            <bounce/>
          </surface>
          <max_contacts>10</max_contacts>
        </collision>
        <collision name='base_link_fixed_joint_lump__caster_wheel_collision_1'>
          <pose>0.14 0 0 0 -0 0</pose>
          <geometry>
            <sphere>
              <radius>0.05</radius>
            </sphere>
          </geometry>
          <surface>
            <contact>
              <ode/>
            </contact>
            <friction>
              <ode>
                <mu>0.001</mu>
                <mu2>0.001</mu2>
              </ode>
              <torsional>
                <ode/>
              </torsional>
            </friction>
            <bounce/>
          </surface>
          <max_contacts>10</max_contacts>
        </collision>
        <visual name='base_link_fixed_joint_lump__chassis_visual'>
          <pose>0.05 0 0.075 0 -0 0</pose>
          <geometry>
            <box>
              <size>0.3 0.3 0.15</size>
            </box>
          </geometry>
          <material>
            <script>
              <name>Gazebo/White</name>
              <uri>file://media/materials/scripts/gazebo.material</uri>
            </script>
          </material>
        </visual>
        <visual name='base_link_fixed_joint_lump__caster_wheel_visual_1'>
          <pose>0.14 0 0 0 -0 0</pose>
          <geometry>
            <sphere>
              <radius>0.05</radius>
            </sphere>
          </geometry>
          <material>
            <script>
              <name>Gazebo/Black</name>
              <uri>file://media/materials/scripts/gazebo.material</uri>
            </script>
          </material>
        </visual>
        <self_collide>0</self_collide>
        <enable_wind>0</enable_wind>
        <kinematic>0</kinematic>
      </link>
      <joint name='left_wheel_joint' type='revolute'>
        <pose relative_to='base_link'>0 0.175 0 -1.5708 0 0</pose>
        <parent>base_link</parent>
        <child>left_wheel</child>
        <axis>
          <xyz>0 0 1</xyz>
          <limit>
            <lower>-1e+16</lower>
            <upper>1e+16</upper>
          </limit>
          <dynamics>
            <spring_reference>0</spring_reference>
            <spring_stiffness>0</spring_stiffness>
          </dynamics>
        </axis>
      </joint>
      <link name='left_wheel'>
        <pose relative_to='left_wheel_joint'>0 0 0 0 -0 0</pose>
        <inertial>
          <pose>0 0 0 0 -0 0</pose>
          <mass>0.1</mass>
          <inertia>
            <ixx>7.58333e-05</ixx>
            <ixy>0</ixy>
            <ixz>0</ixz>
            <iyy>7.58333e-05</iyy>
            <iyz>0</iyz>
            <izz>0.000125</izz>
          </inertia>
        </inertial>
        <collision name='left_wheel_collision'>
          <pose>0 0 0 0 -0 0</pose>
          <geometry>
            <cylinder>
              <length>0.04</length>
              <radius>0.05</radius>
            </cylinder>
          </geometry>
          <surface>
            <contact>
              <ode/>
            </contact>
            <friction>
              <ode/>
              <torsional>
                <ode/>
              </torsional>
            </friction>
            <bounce/>
          </surface>
          <max_contacts>10</max_contacts>
        </collision>
        <visual name='left_wheel_visual'>
          <pose>0 0 0 0 -0 0</pose>
          <geometry>
            <cylinder>
              <length>0.04</length>
              <radius>0.05</radius>
            </cylinder>
          </geometry>
          <material>
            <script>
              <name>Gazebo/Blue</name>
              <uri>file://media/materials/scripts/gazebo.material</uri>
            </script>
          </material>
        </visual>
        <self_collide>0</self_collide>
        <enable_wind>0</enable_wind>
        <kinematic>0</kinematic>
      </link>
      <joint name='right_wheel_joint' type='revolute'>
        <pose relative_to='base_link'>0 -0.175 0 1.5708 -0 0</pose>
        <parent>base_link</parent>
        <child>right_wheel</child>
        <axis>
          <xyz>0 0 -1</xyz>
          <limit>
            <lower>-1e+16</lower>
            <upper>1e+16</upper>
          </limit>
          <dynamics>
            <spring_reference>0</spring_reference>
            <spring_stiffness>0</spring_stiffness>
          </dynamics>
        </axis>
      </joint>
      <link name='right_wheel'>
        <pose relative_to='right_wheel_joint'>0 0 0 0 -0 0</pose>
        <inertial>
          <pose>0 0 0 0 -0 0</pose>
          <mass>0.1</mass>
          <inertia>
            <ixx>7.58333e-05</ixx>
            <ixy>0</ixy>
            <ixz>0</ixz>
            <iyy>7.58333e-05</iyy>
            <iyz>0</iyz>
            <izz>0.000125</izz>
          </inertia>
        </inertial>
        <collision name='right_wheel_collision'>
          <pose>0 0 0 0 -0 0</pose>
          <geometry>
            <cylinder>
              <length>0.04</length>
              <radius>0.05</radius>
            </cylinder>
          </geometry>
          <surface>
            <contact>
              <ode/>
            </contact>
            <friction>
              <ode/>
              <torsional>
                <ode/>
              </torsional>
            </friction>
            <bounce/>
          </surface>
          <max_contacts>10</max_contacts>
        </collision>
        <visual name='right_wheel_visual'>
          <pose>0 0 0 0 -0 0</pose>
          <geometry>
            <cylinder>
              <length>0.04</length>
              <radius>0.05</radius>
            </cylinder>
          </geometry>
          <material>
            <script>
              <name>Gazebo/Blue</name>
              <uri>file://media/materials/scripts/gazebo.material</uri>
            </script>
          </material>
        </visual>
        <self_collide>0</self_collide>
        <enable_wind>0</enable_wind>
        <kinematic>0</kinematic>
      </link>
      <static>0</static>
      <plugin name='diff_drive' filename='libgazebo_ros_diff_drive.so'>
        <left_joint>left_wheel_joint</left_joint>
        <right_joint>right_wheel_joint</right_joint>
        <wheel_seperation>0.35</wheel_seperation>
        <wheel_diameter>0.1</wheel_diameter>
        <max_wheel_torque>150</max_wheel_torque>
        <max_wheel_acceleration>10.0</max_wheel_acceleration>
        <odometry_frame>odum</odometry_frame>
        <robot_base_frame>base_link</robot_base_frame>
        <publish_odom>1</publish_odom>
        <publish_odom_tf>1</publish_odom_tf>
        <publish_wheel_tf>1</publish_wheel_tf>
      </plugin>
      <pose>0 0 0 0 -0 0</pose>
    </model>
    <model name='Kitchen Dining'>
      <static>1</static>
      <link name='link'>
        <visual name='visual'>
          <geometry>
            <mesh>
              <uri>model://kitchen_dining/meshes/kitchen_dining.dae</uri>
            </mesh>
          </geometry>
        </visual>
        <self_collide>0</self_collide>
        <enable_wind>0</enable_wind>
        <kinematic>0</kinematic>
      </link>
      <pose>1.90611 0.942042 0 0 -0 0</pose>
    </model>
    <state world_name='default'>
      <sim_time>318 60000000</sim_time>
      <real_time>319 335161865</real_time>
      <wall_time>1716631022 480680462</wall_time>
      <iterations>318060</iterations>
      <model name='Kitchen Dining'>
        <pose>1.90611 0.942042 0 0 -0 0</pose>
        <scale>1 1 1</scale>
        <link name='link'>
          <pose>1.90611 0.942042 0 0 -0 0</pose>
          <velocity>0 0 0 0 -0 0</velocity>
          <acceleration>0 0 0 0 -0 0</acceleration>
          <wrench>0 0 0 0 -0 0</wrench>
        </link>
      </model>
      <model name='ground_plane'>
        <pose>0 0 0 0 -0 0</pose>
        <scale>1 1 1</scale>
        <link name='link'>
          <pose>0 0 0 0 -0 0</pose>
          <velocity>0 0 0 0 -0 0</velocity>
          <acceleration>0 0 0 0 -0 0</acceleration>
          <wrench>0 0 0 0 -0 0</wrench>
        </link>
      </model>
      <model name='robot_dd'>
        <pose>0.753084 0.444147 0.05 0 0 -2.69717</pose>
        <scale>1 1 1</scale>
        <link name='base_link'>
          <pose>0.753084 0.444147 0.05 0 0 -2.69717</pose>
          <velocity>8.7e-05 4.2e-05 -0 0 0 -1e-05</velocity>
          <acceleration>0 -0 0 1e-06 -1e-06 4e-06</acceleration>
          <wrench>0 -0 0 0 -0 0</wrench>
        </link>
        <link name='left_wheel'>
          <pose>0.828323 0.286147 0.05 -1.5708 -0.622935 -2.69717</pose>
          <velocity>8.5e-05 4.1e-05 -0 -0.00079 0.001652 -1e-05</velocity>
          <acceleration>1e-06 0 0 3e-06 1.1e-05 6e-06</acceleration>
          <wrench>0 0 0 0 -0 0</wrench>
        </link>
        <link name='right_wheel'>
          <pose>0.677844 0.602147 0.05 1.57081 -1.29681 -2.69717</pose>
          <velocity>8.8e-05 4.3e-05 -0 -0.000816 0.00172 -1e-05</velocity>
          <acceleration>-0 -0 0 -4e-06 -9e-06 6e-06</acceleration>
          <wrench>-0 -0 0 0 -0 0</wrench>
        </link>
      </model>
      <light name='sun'>
        <pose>0 0 10 0 -0 0</pose>
      </light>
    </state>
    <gui fullscreen='0'>
      <camera name='user_camera'>
        <pose>0.600764 -3.01787 2.42453 -0 0.399643 1.77701</pose>
        <view_controller>orbit</view_controller>
        <projection_type>perspective</projection_type>
      </camera>
    </gui>
  </world>
</sdf>
