<?xml version="1.0"?>
<robot xmlns:xacro="http://www.ros.org/wiki/xacro">

    <!-- Include inertial macros -->
    <xacro:include filename="inertial.xacro" />


    <!-- Wheels Macro -->
    <xacro:macro name="wheel" params="prefix x_reflect y_reflect">

        <link name="${prefix}_link">
            <visual>
                <origin xyz="0 0 0" rpy="${pi/2} 0 0" />
                <geometry>
                    <cylinder radius="${wheel_radius}" length="${wheel_width}" />
                </geometry>
                <material name="gray">
                    <color rgba="0.3 0.3 0.3 1.0" />
                </material>                                     
            </visual>

            <collision>
                <origin xyz="0 0 0" rpy="${pi/2} 0 0" />
                <geometry>
                    <cylinder radius="${wheel_radius}" length="${wheel_width}" />
                </geometry>
            </collision>

            <xacro:cyclinder_inertia mass="0.5" radius="${wheel_radius}" height="${wheel_width}" />
        </link>

        <joint name="${prefix}_joint" type="continuous">
            <parent link="base_link" />
            <child link="${prefix}_link" />
            <origin
                xyz="${x_reflect*wheel_xoff} ${y_reflect*(base_width/2+wheel_ygap)} ${-wheel_zoff}"
                rpy="0 0 0" />
            <axis xyz="0 1 0" />
        </joint>

        <gazebo reference="${prefix}_link">
            <material>Gazebo/Grey</material>
        </gazebo>

    </xacro:macro>

</robot>